Workbook

Sheet Calculos
C1: receta | D1: =Cocina!C16 -> Guiso de Ternera | F1: indice
D2: =VLOOKUP($D1,Recetas!$A$2:$Q$82,3,0) -> Raw beef | E2: =Cocina!G21 -> 409 | F2: 1 | G2: =IF(Cocina!N14=true,0.15,0) -> 0
D3: =VLOOKUP($D1,Recetas!$A$2:$Q$90,5,0) -> Pumpkin | E3: =Cocina!G22 -> 495 | F3: =IF(D3 = "", F2, F2+1) -> 2 | G3: =IF(Cocina!N13=TRUE,0.59,0) -> 0.59
D4: =VLOOKUP($D1,Recetas!$A$2:$Q$90,7,0) -> Bread | E4: =Cocina!G23 -> 434 | F4: =IF(D4 = "", F3, F3+1) -> 3 | G4: 0.18
D5: =VLOOKUP($D1,Recetas!$A$2:$Q$90,9,0) | E5: =Cocina!G24 -> 245 | F5: =IF(D5 = "", F4, F4+1) -> 3 | G5: =(1-100/(100+(SUM(G2:G4)*100))) -> 0.43502825
D6: Salsa Lv1 | E6: =Cocina!G25 -> 3750 | F6: =IF(D6 = "", F5, F5+1) -> 4 | G6: =Cocina!P14 -> 0.065
D7: Salsa Lv2 | E7: =Cocina!G26 -> 11500 | F7: =IF(D7 = "", F6, F6+1) -> 5
D8: Salsa Lv3 | E8: =Cocina!G27 -> 33502 | F8: =IF(D8 = "", F7, F7+1) -> 6
D9: Energia Ava. | E9: =Cocina!G28 -> 3612 | F9: =IF(D9 = "", F8, F8+1) -> 7
A19: Unidades | B19: Recipe | D19: Costo Unit | E19: Precio Venta | F19: Profit Unit | G19: Profit Bache | H19: Silver/Focus | I19: Foco total | J19: Ingrediente 1 | K19: Cnt | L19: Ingrediente 2 | M19: Cnt | N19: Ingrediente 3 | O19: Cnt | P19: Ingrediente 4 | Q19: Cnt | R19: Sauce | S19: Cnt | T19: Especial | U19: Cnt | V19: Foco/Unidad | W19: Unidades/Crafteo | X19: Comision Estacion | Y19: Para Max LVL | Z19: Fama
A20: =Cocina!K20 | B20: =D1 -> Guiso de Ternera | J20: =VLOOKUP($B20,Recetas!$A$2:$Q$82,3,0) -> Raw beef | K20: =IFERROR(K21*$A20,0) -> 0 | L20: =VLOOKUP($B20,Recetas!$A$2:$Q$90,5,0) -> Pumpkin | M20: =IFERROR(M21*$A20,0) -> 0 | N20: =VLOOKUP($B20,Recetas!$A$2:$Q$90,7,0) -> Bread | O20: =IFERROR(O21*$A20,0) -> 0 | P20: =VLOOKUP($B20,Recetas!$A$2:$Q$90,9,0) | Q20: =IFERROR(Q21*$A20,0) -> 0 | R20: =VLOOKUP($B20,Recetas!$A$2:$Q$90,13,0) | S20: =IFERROR(S21*$A20,0) -> 0 | T20: =VLOOKUP($B20,Recetas!$A$2:$Q$90,11,0) | U20: =IFERROR(U21*$A20,0) -> 0 | Y20: =IFERROR(VLOOKUP(VLOOKUP($B20,Recetas!$A$2:$R$69,18,0),Cocina!$E$13:$H$16,5,0)/Z20,"-") -> - | Z20: =IF(VLOOKUP($B20,Recetas!$A$2:$Q$90,16,0) <> "", VLOOKUP($B20,Recetas!$A$2:$Q$90,16,0), 0) -> 4320
D21: =IFERROR(((((J21*K21)+(L21*M21)+(N21*O21)+(P21*Q21)+(R21*S21))*(1-$G$5))+X21+(T21*U21))/W21,"") -> 3935.5403 | E21: =IF(Calculos!B20 <> "",VLOOKUP(Calculos!B20,'Lista de Precios'!F$3:H$92,3,0),"") -> 3989 | F21: =IFERROR((E21-(E21*G$6)-D21),"?") -> -205.82534 | G21: =IFERROR((F21*W21)/V21*I21,"0") -> 0 | H21: =IFERROR((F21*W21)/V21,"?") -> -14.554247 | I21: =A20*V21 -> 0 | J21: =IF(J20 ="",0, VLOOKUP(J20,$D$2:$E$9,2,0)) -> 409 | K21: =VLOOKUP($B20,Recetas!$A$2:$Q$90,4,0) -> 72 | L21: =IF(L20 ="",0, VLOOKUP(L20,$D$2:$E$9,2,0)) -> 495 | M21: =VLOOKUP($B20,Recetas!$A$2:$Q$90,6,0) -> 36 | N21: =IF(N20 ="",0, VLOOKUP(N20,$D$2:$E$9,2,0)) -> 434 | O21: =VLOOKUP($B20,Recetas!$A$2:$Q$90,8,0) -> 36 | P21: =IF(P20 ="",0, VLOOKUP(P20,$D$2:$E$9,2,0)) -> 0 | Q21: =VLOOKUP($B20,Recetas!$A$2:$Q$90,10,0) | R21: =IF(R20 ="",0, VLOOKUP(R20,$D$2:$E$9,2,0)) -> 0 | S21: =VLOOKUP($B20,Recetas!$A$2:$Q$90,14,0) -> 90 | T21: =IF(T20 ="",0, VLOOKUP(T20,$D$2:$E$9,2,0)) -> 0 | U21: =VLOOKUP($B20,Recetas!$A$2:$Q$90,12,0) | V21: =VLOOKUP($B20,Recetas!$A$2:$Q$90,2,0) * VLOOKUP(VLOOKUP($B20,Recetas!$A$2:$R$90,18,0),Recetas!$T$2:$U$10,2,0) -> 141.41944 | W21: =VLOOKUP($B20,Recetas!$A$2:$Q$90,15,0) -> 10 | X21: =0.1125*VLOOKUP($B20,Recetas!$A$2:$Q$90,17,0)*(Cocina!$P$12/10)/(10/VLOOKUP($B20,Recetas!$A$2:$Q$90,15,0)) -> 3823.2 | AA21: =IFERROR(X21*A20,0) -> 0
A22: =Cocina!K23 -> 45 | B22: =$D$1 & " .1" -> Guiso de Ternera .1 | J22: =VLOOKUP($B22,Recetas!$A$2:$Q$82,3,0) -> Raw beef | K22: =IFERROR(K23*$A22,0) -> 3240 | L22: =VLOOKUP($B22,Recetas!$A$2:$Q$90,5,0) -> Pumpkin | M22: =IFERROR(M23*$A22,0) -> 1620 | N22: =VLOOKUP($B22,Recetas!$A$2:$Q$90,7,0) -> Bread | O22: =IFERROR(O23*$A22,0) -> 1620 | P22: =VLOOKUP($B22,Recetas!$A$2:$Q$90,9,0) | Q22: =IFERROR(Q23*$A22,0) -> 0 | R22: =VLOOKUP($B22,Recetas!$A$2:$Q$90,13,0) -> Salsa Lv1 | S22: =IFERROR(S23*$A22,0) -> 4050 | T22: =VLOOKUP($B22,Recetas!$A$2:$Q$90,11,0) | U22: =IFERROR(U23*$A22,0) -> 0 | Y22: =IFERROR(VLOOKUP(VLOOKUP($B22,Recetas!$A$2:$R$69,18,0),Cocina!$E$13:$H$16,5,0)/Z22,"-") -> - | Z22: =IF(VLOOKUP($B22,Recetas!$A$2:$Q$90,16,0) <> "", VLOOKUP($B22,Recetas!$A$2:$Q$90,16,0), 0) -> 0
D23: =IFERROR(((((J23*K23)+(L23*M23)+(N23*O23)+(P23*Q23)+(R23*S23))*(1-$G$5))+X23+(T23*U23))/W23,"") -> 23003.337 | E23: =IF(Calculos!B22 <> "",VLOOKUP(Calculos!B22,'Lista de Precios'!F$3:H$92,3,0),"") -> 28786 | F23: =IFERROR((E23-(E23*G$6)-D23),"?") -> 3911.5731 | G23: =IFERROR((F23*W23)/V23*I23,"0") -> 1760207.9 | H23: =IFERROR((F23*W23)/V23,"?") -> 202.66376 | I23: =A22*V23 -> 8685.3607 | J23: =IF(J22 ="",0, VLOOKUP(J22,$D$2:$E$9,2,0)) -> 409 | K23: =VLOOKUP($B22,Recetas!$A$2:$Q$90,4,0) -> 72 | L23: =IF(L22 ="",0, VLOOKUP(L22,$D$2:$E$9,2,0)) -> 495 | M23: =VLOOKUP($B22,Recetas!$A$2:$Q$90,6,0) -> 36 | N23: =IF(N22 ="",0, VLOOKUP(N22,$D$2:$E$9,2,0)) -> 434 | O23: =VLOOKUP($B22,Recetas!$A$2:$Q$90,8,0) -> 36 | P23: =IF(P22 ="",0, VLOOKUP(P22,$D$2:$E$9,2,0)) -> 0 | Q23: =VLOOKUP($B22,Recetas!$A$2:$Q$90,10,0) | R23: =IF(R22 ="",0, VLOOKUP(R22,$D$2:$E$9,2,0)) -> 3750 | S23: =VLOOKUP($B22,Recetas!$A$2:$Q$90,14,0) -> 90 | T23: =IF(T22 ="",0, VLOOKUP(T22,$D$2:$E$9,2,0)) -> 0 | U23: =VLOOKUP($B22,Recetas!$A$2:$Q$90,12,0) | V23: =VLOOKUP($B22,Recetas!$A$2:$Q$90,2,0) * VLOOKUP(VLOOKUP($B22,Recetas!$A$2:$R$90,18,0),Recetas!$T$2:$U$10,2,0) -> 193.00801 | W23: =VLOOKUP($B22,Recetas!$A$2:$Q$90,15,0) -> 10 | X23: =0.1125*VLOOKUP($B22,Recetas!$A$2:$Q$90,17,0)*(Cocina!$P$12/10)/(10/VLOOKUP($B22,Recetas!$A$2:$Q$90,15,0)) -> 3823.2 | AA23: =IFERROR(X23*A22,0) -> 172044
A24: =Cocina!K26 -> 24 | B24: =$D$1 & " .2" -> Guiso de Ternera .2 | J24: =VLOOKUP($B24,Recetas!$A$2:$Q$82,3,0) -> Raw beef | K24: =IFERROR(K25*$A24,0) -> 1728 | L24: =VLOOKUP($B24,Recetas!$A$2:$Q$90,5,0) -> Pumpkin | M24: =IFERROR(M25*$A24,0) -> 864 | N24: =VLOOKUP($B24,Recetas!$A$2:$Q$90,7,0) -> Bread | O24: =IFERROR(O25*$A24,0) -> 864 | P24: =VLOOKUP($B24,Recetas!$A$2:$Q$90,9,0) | Q24: =IFERROR(Q25*$A24,0) -> 0 | R24: =VLOOKUP($B24,Recetas!$A$2:$Q$90,13,0) -> Salsa Lv2 | S24: =IFERROR(S25*$A24,0) -> 2160 | T24: =VLOOKUP($B24,Recetas!$A$2:$Q$90,11,0) | U24: =IFERROR(U25*$A24,0) -> 0 | Y24: =IFERROR(VLOOKUP(VLOOKUP($B24,Recetas!$A$2:$R$69,18,0),Cocina!$E$13:$H$16,5,0)/Z24,"-") -> - | Z24: =IF(VLOOKUP($B24,Recetas!$A$2:$Q$90,16,0) <> "", VLOOKUP($B24,Recetas!$A$2:$Q$90,16,0), 0) -> 0
D25: =IFERROR(((((J25*K25)+(L25*M25)+(N25*O25)+(P25*Q25)+(R25*S25))*(1-$G$5))+X25+(T25*U25))/W25,"") -> 62410.117 | E25: =IF(Calculos!B24 <> "",VLOOKUP(Calculos!B24,'Lista de Precios'!F$3:H$92,3,0),"") -> 78000 | F25: =IFERROR((E25-(E25*G$6)-D25),"?") -> 10519.883 | G25: =IFERROR((F25*W25)/V25*I25,"0") -> 2524772 | H25: =IFERROR((F25*W25)/V25,"?") -> 355.7959 | I25: =A24*V25 -> 7096.1245 | J25: =IF(J24 ="",0, VLOOKUP(J24,$D$2:$E$9,2,0)) -> 409 | K25: =VLOOKUP($B24,Recetas!$A$2:$Q$90,4,0) -> 72 | L25: =IF(L24 ="",0, VLOOKUP(L24,$D$2:$E$9,2,0)) -> 495 | M25: =VLOOKUP($B24,Recetas!$A$2:$Q$90,6,0) -> 36 | N25: =IF(N24 ="",0, VLOOKUP(N24,$D$2:$E$9,2,0)) -> 434 | O25: =VLOOKUP($B24,Recetas!$A$2:$Q$90,8,0) -> 36 | P25: =IF(P24 ="",0, VLOOKUP(P24,$D$2:$E$9,2,0)) -> 0 | Q25: =VLOOKUP($B24,Recetas!$A$2:$Q$90,10,0) | R25: =IF(R24 ="",0, VLOOKUP(R24,$D$2:$E$9,2,0)) -> 11500 | S25: =VLOOKUP($B24,Recetas!$A$2:$Q$90,14,0) -> 90 | T25: =IF(T24 ="",0, VLOOKUP(T24,$D$2:$E$9,2,0)) -> 0 | U25: =VLOOKUP($B24,Recetas!$A$2:$Q$90,12,0) | V25: =VLOOKUP($B24,Recetas!$A$2:$Q$90,2,0) * VLOOKUP(VLOOKUP($B24,Recetas!$A$2:$R$90,18,0),Recetas!$T$2:$U$10,2,0) -> 295.67185 | W25: =VLOOKUP($B24,Recetas!$A$2:$Q$90,15,0) -> 10 | X25: =0.1125*VLOOKUP($B24,Recetas!$A$2:$Q$90,17,0)*(Cocina!$P$12/10)/(10/VLOOKUP($B24,Recetas!$A$2:$Q$90,15,0)) -> 3823.2 | AA25: =IFERROR(X25*A24,0) -> 91756.8
A26: =Cocina!K29 | B26: =$D$1 & " .3" -> Guiso de Ternera .3 | J26: =VLOOKUP($B26,Recetas!$A$2:$Q$82,3,0) -> Raw beef | K26: =IFERROR(K27*$A26,0) -> 0 | L26: =VLOOKUP($B26,Recetas!$A$2:$Q$90,5,0) -> Pumpkin | M26: =IFERROR(M27*$A26,0) -> 0 | N26: =VLOOKUP($B26,Recetas!$A$2:$Q$90,7,0) -> Bread | O26: =IFERROR(O27*$A26,0) -> 0 | P26: =VLOOKUP($B26,Recetas!$A$2:$Q$90,9,0) | Q26: =IFERROR(Q27*$A26,0) -> 0 | R26: =VLOOKUP($B26,Recetas!$A$2:$Q$90,13,0) -> Salsa Lv3 | S26: =IFERROR(S27*$A26,0) -> 0 | T26: =VLOOKUP($B26,Recetas!$A$2:$Q$90,11,0) | U26: =IFERROR(U27*$A26,0) -> 0 | Y26: =IFERROR(VLOOKUP(VLOOKUP($B26,Recetas!$A$2:$R$69,18,0),Cocina!$E$13:$H$16,5,0)/Z26,"-") -> - | Z26: =IF(VLOOKUP($B26,Recetas!$A$2:$Q$90,16,0) <> "", VLOOKUP($B26,Recetas!$A$2:$Q$90,16,0), 0) -> 0
D27: =IFERROR(((((J27*K27)+(L27*M27)+(N27*O27)+(P27*Q27)+(R27*S27))*(1-$G$5))+X27+(T27*U27))/W27,"") -> 174284.69 | E27: =IF(Calculos!B26 <> "",VLOOKUP(Calculos!B26,'Lista de Precios'!F$3:H$92,3,0),"") -> 198000 | F27: =IFERROR((E27-(E27*G$6)-D27),"?") -> 10845.307 | G27: =IFERROR((F27*W27)/V27*I27,"0") -> 0 | H27: =IFERROR((F27*W27)/V27,"?") -> 179.58184 | I27: =A26*V27 -> 0 | J27: =IF(J26 ="",0, VLOOKUP(J26,$D$2:$E$9,2,0)) -> 409 | K27: =VLOOKUP($B26,Recetas!$A$2:$Q$90,4,0) -> 72 | L27: =IF(L26 ="",0, VLOOKUP(L26,$D$2:$E$9,2,0)) -> 495 | M27: =VLOOKUP($B26,Recetas!$A$2:$Q$90,6,0) -> 36 | N27: =IF(N26 ="",0, VLOOKUP(N26,$D$2:$E$9,2,0)) -> 434 | O27: =VLOOKUP($B26,Recetas!$A$2:$Q$90,8,0) -> 36 | P27: =IF(P26 ="",0, VLOOKUP(P26,$D$2:$E$9,2,0)) -> 0 | Q27: =VLOOKUP($B26,Recetas!$A$2:$Q$90,10,0) | R27: =IF(R26 ="",0, VLOOKUP(R26,$D$2:$E$9,2,0)) -> 33502 | S27: =VLOOKUP($B26,Recetas!$A$2:$Q$90,14,0) -> 90 | T27: =IF(T26 ="",0, VLOOKUP(T26,$D$2:$E$9,2,0)) -> 0 | U27: =VLOOKUP($B26,Recetas!$A$2:$Q$90,12,0) | V27: =VLOOKUP($B26,Recetas!$A$2:$Q$90,2,0) * VLOOKUP(VLOOKUP($B26,Recetas!$A$2:$R$90,18,0),Recetas!$T$2:$U$10,2,0) -> 603.92002 | W27: =VLOOKUP($B26,Recetas!$A$2:$Q$90,15,0) -> 10 | X27: =0.1125*VLOOKUP($B26,Recetas!$A$2:$Q$90,17,0)*(Cocina!$P$12/10)/(10/VLOOKUP($B26,Recetas!$A$2:$Q$90,15,0)) -> 3823.2 | AA27: =IFERROR(X27*A26,0) -> 0
K28: =SUM(K20,K22,K26,K24) -> 4968 | M28: =SUM(M20,M22,M26,M24) -> 2484 | O28: =SUM(O20,O22,O26,O24) -> 2484 | Q28: =SUM(Q20,Q22,Q26,Q24) -> 0 | S28: =S22 -> 4050 | U28: =SUM(U20,U22,U26,U24) -> 0 | AA28: =SUM(AA21:AA27) -> 263800.8
S29: =S24 -> 2160
S30: =S26 -> 0

Sheet Recetas
A1: Nombre | B1: Base Focus | C1: Igrediente 1 | D1: Cnt | E1: Igrediente 2 | F1: Cnt | G1: Igrediente 3 | H1: Cnt | I1: Igrediente 4 | J1: Cnt | K1: Energia Ava | L1: Cnt | M1: Salsa | N1: Cnt | O1: Unidades | P1: Fama | Q1: IV | R1: Tipo | T1: Eficiencia de Foco | U1: Factor | V1: 0 | W1: 0 | X1: 0 | AA1: Carrot
A2: Sopa de Zanahorias | B2: 560 | C2: Carrot | D2: 16 | O2: 10 | P2: 480 | Q2: 64 | R2: Sopas | T2: Carniceria | U2: =Recetas!U13 -> 0.025665959 | V2: 1 | W2: 3564 | X2: =W2 -> 3564 | AA2: Bean
A3: Ensalada de Frijoles | B3: 560 | C3: Bean | D3: 8 | E3: Carrot | F3: 8 | O3: 10 | P3: 480 | Q3: 64 | R3: Ensaladas | T3: Ingredientes | U3: =Recetas!U14 -> 0.059995579 | V3: 2 | W3: 3784 | X3: =W3+X2 -> 7348 | AA3: Wheat
A4: Sopa de Trigo | B4: 1680 | C4: Wheat | D4: 48 | O4: 10 | P4: 1440 | Q4: 192 | R4: Sopas | T4: Bocadillos | U4: =Recetas!U15 -> 0.025665959 | V4: 3 | W4: 4008 | X4: =W4+X3 -> 11356 | AA4: Turnip
A5: Pastel de Pollo | B5: 530 | C5: Wheat | D5: 2 | E5: Flour | F5: 4 | G5: Raw chicken | H5: 8 | O5: 10 | P5: 180 | Q5: 56 | R5: Pasteles | T5: Guisos | U5: =Recetas!U16 -> 0.025665959 | V5: 4 | W5: 4240 | X5: =W5+X4 -> 15596 | AA5: Cabbage
A6: Tortilla de Pollo | B6: 520 | C6: Wheat | D6: 4 | E6: Raw chicken | F6: 8 | G6: Hen eggs | H6: 2 | O6: 10 | P6: 180 | Q6: 56 | R6: Tortillas | T6: Tortillas | U6: =Recetas!U17 -> 0.025665959 | V6: 5 | W6: 4480 | X6: =W6+X5 -> 20076 | AA6: Potatoes
A7: Pollo Asado | B7: 580 | C7: Raw chicken | D7: 8 | E7: Bean | F7: 4 | G7: Goat's milk | H7: 4 | O7: 10 | P7: 480 | Q7: 64 | R7: Asados | T7: Asados | U7: =Recetas!U20 -> 0.025665959 | V7: 6 | W7: 4728 | X7: =W7+X6 -> 24804 | AA7: Bundle of corn
A8: Ensalada de Rábanos | B8: 1680 | C8: Turnip | D8: 24 | E8: Wheat | F8: 24 | O8: 10 | P8: 1440 | Q8: 192 | R8: Ensaladas | T8: Pasteles | U8: =Recetas!U19 -> 0.038234001 | V8: 7 | W8: 4988 | X8: =W8+X7 -> 29792 | AA8: Pumpkin
A9: Guiso de Cabra | B9: 610 | C9: Turnip | D9: 4 | E9: Bread | F9: 4 | G9: Raw goat | H9: 8 | O9: 10 | P9: 480 | Q9: 64 | R9: Guisos | T9: Ensaladas | U9: =Recetas!U18 -> 0.025665959 | V9: 8 | W9: 5252 | X9: =W9+X8 -> 35044 | AA9: Dragon teasel
A10: Bocadillo de Cabra | B10: 550 | C10: Goat's butter | D10: 2 | E10: Bread | F10: 4 | G10: Raw goat | H10: 8 | O10: 10 | P10: 420 | Q10: 56 | R10: Bocadillos | T10: Sopas | U10: =Recetas!U21 -> 0.025665959 | V10: 9 | W10: 5524 | X10: =W10+X9 -> 40568 | AA10: Elusive Foxglove
A11: Sopa de Col | B11: 5040 | C11: Cabbage | D11: 144 | O11: 10 | P11: 4320 | Q11: 576 | R11: Sopas | V11: 10 | W11: 5808 | X11: =W11+X10 -> 46376 | AA11: Firetouched mullein
A12: Pastel de Ganso | B12: 1800 | C12: Cabbage | D12: 6 | E12: Flour | F12: 12 | G12: Raw goose | H12: 24 | I12: Goat's milk | J12: 6 | O12: 10 | P12: 720 | Q12: 192 | R12: Pasteles | T12: Eficiencia de Foco | U12: Factor | V12: 11 | W12: 6100 | X12: =W12+X11 -> 52476 | AA12: Ghoul Yarrow
A13: Tortilla de Ganso | B13: 1550 | C13: Cabbage | D13: 12 | E13: Raw goose | F13: 24 | G13: Goose eggs | H13: 6 | O13: 10 | P13: 1260 | Q13: 168 | R13: Tortillas | T13: Carniceria | U13: =0.5^((2.8*Cocina!E9 + 0.3*(Cocina!E8 + Cocina!E10 + Cocina!E11 + Cocina!E12 + Cocina!H8 + Cocina!H9 +Cocina!H10 + Cocina!H11 + Cocina!H12))/100) -> 0.025665959 | V13: 12 | W13: 6400 | X13: =W13+X12 -> 58876 | AA13: Raw chicken
A14: Ganso Asado | B14: 1760 | C14: Raw goose | D14: 24 | E14: Cabbage | F14: 12 | G14: Sheep's milk | H14: 12 | O14: 10 | P14: 1440 | Q14: 192 | R14: Asados | T14: Ingredientes | U14: =0.5^((2.8*Cocina!E10 + 0.3*(Cocina!E8 + Cocina!E9 + Cocina!E11 + Cocina!E12 + Cocina!H8 + Cocina!H9 +Cocina!H10 + Cocina!H11 + Cocina!H12))/100) -> 0.059995579 | V14: 13 | W14: 6712 | X14: =W14+X13 -> 65588 | AA14: Raw goat
A15: Ensalada de Patatas | B15: 5040 | C15: Cabbage | D15: 72 | E15: Potatoes | F15: 72 | O15: 10 | P15: 4320 | Q15: 576 | R15: Ensaladas | T15: Bocadillos | U15: =0.5^((2.8*Cocina!E11 + 0.3*(Cocina!E8 + Cocina!E9 + Cocina!E10 + Cocina!E12 + Cocina!H8 + Cocina!H9 +Cocina!H10 + Cocina!H11 + Cocina!H12))/100) -> 0.025665959 | V15: 14 | W15: 7032 | X15: =W15+X14 -> 72620 | AA15: Raw Goose
A16: Ensalada de Kraken | B16: 672 | C16: Deepwater Kraken | D16: 1 | E16: Elusive Foxglove | F16: 6 | G16: Raw mutton | H16: 6 | I16: Potatoes | J16: 6 | N16: 27 | O16: 1 | P16: 360 | Q16: 750 | R16: Ensaladas | T16: Guisos | U16: =0.5^((2.8*Cocina!E12 + 0.3*(Cocina!E8 + Cocina!E9 + Cocina!E10 + Cocina!E11 + Cocina!H8 + Cocina!H9 +Cocina!H10 + Cocina!H11 + Cocina!H12))/100) -> 0.025665959 | V16: 15 | W16: 7364 | X16: =W16+X15 -> 79984 | AA16: Raw mutton
A17: Ensalada de Kraken .1 | B17: 1272 | C17: Deepwater Kraken | D17: 1 | E17: Elusive Foxglove | F17: 6 | G17: Raw mutton | H17: 6 | I17: Potatoes | J17: 6 | M17: Salsa Lv1 | N17: 27 | O17: 1 | P17: 765 | Q17: 750 | R17: Ensaladas | T17: Tortillas | U17: =0.5^((2.8*Cocina!H8 + 0.3*(Cocina!E8 + Cocina!E9 + Cocina!E10 + Cocina!E11 + Cocina!E12 + Cocina!H9 +Cocina!H10 + Cocina!H11 + Cocina!H12))/100) -> 0.025665959 | V17: 16 | W17: 7704 | X17: =W17+X16 -> 87688 | AA17: Raw pork
A18: Ensalada de Kraken .2 | B18: 2473 | C18: Deepwater Kraken | D18: 1 | E18: Elusive Foxglove | F18: 6 | G18: Raw mutton | H18: 6 | I18: Potatoes | J18: 6 | M18: Salsa Lv2 | N18: 27 | O18: 1 | Q18: 750 | R18: Ensaladas | T18: Asados | U18: =0.5^((2.8*Cocina!H9 + 0.3*(Cocina!E8 + Cocina!E9 + Cocina!E10 + Cocina!E11 + Cocina!E12 + Cocina!H8 +Cocina!H10 + Cocina!H11 + Cocina!H12))/100) -> 0.025665959 | V18: 17 | W18: 8056 | X18: =W18+X17 -> 95744 | AA18: Raw beef
A19: Ensalada de Kraken .3 | B19: 6076 | C19: Deepwater Kraken | D19: 1 | E19: Elusive Foxglove | F19: 6 | G19: Raw mutton | H19: 6 | I19: Potatoes | J19: 6 | M19: Salsa Lv3 | N19: 27 | O19: 1 | Q19: 750 | R19: Ensaladas | T19: Pasteles | U19: =0.5^((2.8*Cocina!H10 + 0.3*(Cocina!E8 + Cocina!E9 + Cocina!E10 + Cocina!E11 + Cocina!E12 + Cocina!H8 + Cocina!H9 +Cocina!H11 + Cocina!H12))/100) -> 0.038234001 | V19: 18 | W19: 8420 | X19: =W19+X18 -> 104164 | AA19: Hen eggs
A20: Guiso de Carnero | B20: 1840 | C20: Potatoes | D20: 12 | E20: Bread | F20: 12 | G20: Raw mutton | H20: 24 | O20: 10 | P20: 1440 | Q20: 192 | R20: Guisos | T20: Ensaladas | U20: =(0.5)^((2.8*Cocina!H11 + 0.3*(Cocina!E8 + Cocina!E9 + Cocina!E10 + Cocina!E11 + Cocina!E12 + Cocina!H8 + Cocina!H9 +Cocina!H10 + Cocina!H12))/100) -> 0.025665959 | V20: 19 | W20: 8792 | X20: =W20+X19 -> 112956 | AA20: Flour
A21: Bocadillo de Carnero | B21: 1650 | C21: sheep's butter | D21: 6 | E21: Bread | F21: 12 | G21: Raw mutton | H21: 24 | O21: 10 | P21: 1260 | Q21: 168 | R21: Bocadillos | T21: Sopas | U21: =(0.5)^((2.8*Cocina!H12 + 0.3*(Cocina!E8 + Cocina!E9 + Cocina!E10 + Cocina!E11 + Cocina!E12 + Cocina!H8 +Cocina!H9+ Cocina!H10 + Cocina!H11))/100) -> 0.025665959 | V21: 20 | W21: 9176 | X21: =W21+X20 -> 122132 | AA21: Bread
A22: Pastel de Cerdo | B22: 5400 | C22: Raw pork | D22: 72 | E22: Flour | F22: 36 | G22: Bundle of corn | H22: 18 | I22: Sheep's milk | J22: 18 | N22: 90 | O22: 10 | P22: 4320 | Q22: 576 | R22: Pasteles | S22: Fama actual | T22: Nivel Meta | U22: Fama Requerida | V22: 21 | W22: 9576 | X22: =W22+X21 -> 131708 | AA22: Goat's butter
A23: Pastel de Cerdo .1 | B23: 7390 | C23: Raw pork | D23: 72 | E23: Flour | F23: 36 | G23: Bundle of corn | H23: 18 | I23: Sheep's milk | J23: 18 | M23: Salsa Lv1 | N23: 90 | O23: 10 | Q23: 576 | R23: Pasteles | S23: - | T23: - | U23: - | V23: 22 | W23: 9984 | X23: =W23+X22 -> 141692 | AA23: Goat's milk
A24: Pastel de Cerdo .2 | B24: 11400 | C24: Raw pork | D24: 72 | E24: Flour | F24: 36 | G24: Bundle of corn | H24: 18 | I24: Sheep's milk | J24: 18 | M24: Salsa Lv2 | N24: 90 | O24: 10 | Q24: 576 | R24: Pasteles | S24: 0 | T24: 100 | U24: {=IFERROR(IF(INDEX(Recetas!$X$2:$X$101,T24,1)-INDEX(Recetas!$X$2:$X$101,Cocina!E9,1)-S24 < 0, 0, INDEX(Recetas!$X$2:$X$101,T24,1)-INDEX(Recetas!$X$2:$X$101,Cocina!E9,1)-S24), 0)} -> 0 | V24: 23 | W24: 10408 | X24: =W24+X23 -> 152100 | AA24: Goose eggs
A25: Pastel de Cerdo .3 | B25: 23410 | C25: Raw pork | D25: 72 | E25: Flour | F25: 36 | G25: Bundle of corn | H25: 18 | I25: Sheep's milk | J25: 18 | M25: Salsa Lv3 | N25: 90 | O25: 10 | Q25: 576 | R25: Pasteles | S25: 0 | T25: 100 | U25: {=IFERROR(IF(INDEX(Recetas!$X$2:$X$101,T25,1)-INDEX(Recetas!$X$2:$X$101,Cocina!E10,1)-S25 < 0, 0, INDEX(Recetas!$X$2:$X$101,T25,1)-INDEX(Recetas!$X$2:$X$101,Cocina!E10,1)-S25), 0)} -> 3357664 | V25: 24 | W25: 10844 | X25: =W25+X24 -> 162944 | AA25: sheep's butter
A26: Tortilla de Cerdo | B26: 4640 | C26: Bundle of corn | D26: 36 | E26: Goose eggs | F26: 18 | G26: Raw pork | H26: 72 | N26: 90 | O26: 10 | P26: 3780 | Q26: 504 | R26: Tortillas | S26: 0 | T26: 100 | U26: {=IFERROR(IF(INDEX(Recetas!$X$2:$X$101,T26,1)-INDEX(Recetas!$X$2:$X$101,Cocina!E11,1)-S26 < 0, 0, INDEX(Recetas!$X$2:$X$101,T26,1)-INDEX(Recetas!$X$2:$X$101,Cocina!E11,1)-S26), 0)} -> 0 | V26: 25 | W26: 11292 | X26: =W26+X25 -> 174236 | AA26: Sheep's milk
A27: Tortilla de Cerdo .1 | B27: 6650 | C27: Bundle of corn | D27: 36 | E27: Goose eggs | F27: 18 | G27: Raw pork | H27: 72 | M27: Salsa Lv1 | N27: 90 | O27: 10 | P27: 3780 | Q27: 504 | R27: Tortillas | S27: 0 | T27: 100 | U27: {=IFERROR(IF(INDEX(Recetas!$X$2:$X$101,T27,1)-INDEX(Recetas!$X$2:$X$101,Cocina!E12,1)-S27 < 0, 0, INDEX(Recetas!$X$2:$X$101,T27,1)-INDEX(Recetas!$X$2:$X$101,Cocina!E12,1)-S27), 0)} -> 0 | V27: 26 | W27: 11752 | X27: =W27+X26 -> 185988 | AA27: Cow's milk
A28: Tortilla de Cerdo .2 | B28: 10650 | C28: Bundle of corn | D28: 36 | E28: Goose eggs | F28: 18 | G28: Raw pork | H28: 72 | M28: Salsa Lv2 | N28: 90 | O28: 10 | P28: 3780 | Q28: 504 | R28: Tortillas | S28: 0 | T28: 100 | U28: {=IFERROR(IF(INDEX(Recetas!$X$2:$X$101,T28,1)-INDEX(Recetas!$X$2:$X$101,Cocina!H8,1)-S28 < 0, 0, INDEX(Recetas!$X$2:$X$101,T28,1)-INDEX(Recetas!$X$2:$X$101,Cocina!H8,1)-S28), 0)} -> 0 | V28: 27 | W28: 12228 | X28: =W28+X27 -> 198216 | AA28: Cow's butter
A29: Tortilla de Cerdo .3 | B29: 22660 | C29: Bundle of corn | D29: 36 | E29: Goose eggs | F29: 18 | G29: Raw pork | H29: 72 | M29: Salsa Lv3 | N29: 90 | O29: 10 | Q29: 504 | R29: Tortillas | S29: 0 | T29: 100 | U29: {=IFERROR(IF(INDEX(Recetas!$X$2:$X$101,T29,1)-INDEX(Recetas!$X$2:$X$101,Cocina!H9,1)-S29 < 0, 0, INDEX(Recetas!$X$2:$X$101,T29,1)-INDEX(Recetas!$X$2:$X$101,Cocina!H9,1)-S29), 0)} -> 0 | V29: 28 | W29: 12720 | X29: =W29+X28 -> 210936 | AA29: Deepwater Kraken
A30: Pastel de Ojo Muerto | B30: 672 | C30: Frostpeak Deadeye | D30: 1 | E30: Bundle of corn | F30: 6 | G30: Firetouched mullein | H30: 6 | I30: Raw pork | J30: 6 | N30: 27 | O30: 1 | Q30: 750 | R30: Pasteles | S30: 0 | T30: 100 | U30: {=IFERROR(IF(INDEX(Recetas!$X$2:$X$101,T30,1)-INDEX(Recetas!$X$2:$X$101,Cocina!H10,1)-S30 < 0, 0, INDEX(Recetas!$X$2:$X$101,T30,1)-INDEX(Recetas!$X$2:$X$101,Cocina!H10,1)-S30), 0)} -> 2168168 | V30: 29 | W30: 13224 | X30: =W30+X29 -> 224160 | AA30: Frostpeak Deadeye
A31: Pastel de Ojo Muerto .1 | B31: 1272 | C31: Frostpeak Deadeye | D31: 1 | E31: Bundle of corn | F31: 6 | G31: Firetouched mullein | H31: 6 | I31: Raw pork | J31: 6 | M31: Salsa Lv1 | N31: 27 | O31: 1 | Q31: 750 | R31: Pasteles | S31: 0 | T31: 100 | U31: {=IFERROR(IF(INDEX(Recetas!$X$2:$X$101,T31,1)-INDEX(Recetas!$X$2:$X$101,Cocina!H11,1)-S31 < 0, 0, INDEX(Recetas!$X$2:$X$101,T31,1)-INDEX(Recetas!$X$2:$X$101,Cocina!H11,1)-S31), 0)} -> 0 | V31: 30 | W31: 13744 | X31: =W31+X30 -> 237904 | AA31: Dusthole Crab
A32: Pastel de Ojo Muerto .2 | B32: 2473 | C32: Frostpeak Deadeye | D32: 1 | E32: Bundle of corn | F32: 6 | G32: Firetouched mullein | H32: 6 | I32: Raw pork | J32: 6 | M32: Salsa Lv2 | N32: 27 | O32: 1 | Q32: 750 | R32: Pasteles | S32: 0 | T32: 100 | U32: {=IFERROR(IF(INDEX(Recetas!$X$2:$X$101,T32,1)-INDEX(Recetas!$X$2:$X$101,Cocina!H12,1)-S32 < 0, 0, INDEX(Recetas!$X$2:$X$101,T32,1)-INDEX(Recetas!$X$2:$X$101,Cocina!H12,1)-S32), 0)} -> 0 | V32: 31 | W32: 14280 | X32: =W32+X31 -> 252184 | AA32: Deadwater Eel
A33: Pastel de Ojo Muerto .3 | B33: 6076 | C33: Frostpeak Deadeye | D33: 1 | E33: Bundle of corn | F33: 6 | G33: Firetouched mullein | H33: 6 | I33: Raw pork | J33: 6 | M33: Salsa Lv3 | N33: 27 | O33: 1 | Q33: 750 | R33: Pasteles | V33: 32 | W33: 14832 | X33: =W33+X32 -> 267016 | AA33: Puremist Snapper
A34: Tortilla de Cangrejo | B34: 788 | C34: Dusthole Crab | D34: 1 | E34: Bundle of corn | F34: 6 | G34: Firetouched mullein | H34: 6 | I34: Raw pork | J34: 6 | N34: 27 | O34: 1 | P34: 540 | Q34: 750 | R34: Tortillas | S34: 132 | T34: 64 | V34: 33 | W34: 15400 | X34: =W34+X33 -> 282416 | AA34: Thunderfall lurcher
A35: Tortilla de Cangrejo .1 | B35: 1272 | C35: Dusthole Crab | D35: 1 | E35: Bundle of corn | F35: 6 | G35: Firetouched mullein | H35: 6 | I35: Raw pork | J35: 6 | M35: Salsa Lv1 | N35: 27 | O35: 1 | Q35: 750 | R35: Tortillas | S35: 132 | T35: 64 | V35: 34 | W35: 15984 | X35: =W35+X34 -> 298400 | AA35: Salsa Lv1
A36: Tortilla de Cangrejo .2 | B36: 2473 | C36: Dusthole Crab | D36: 1 | E36: Bundle of corn | F36: 6 | G36: Firetouched mullein | H36: 6 | I36: Raw pork | J36: 6 | M36: Salsa Lv2 | N36: 27 | O36: 1 | Q36: 750 | R36: Tortillas | S36: 396 | T36: 192 | V36: 35 | W36: 16588 | X36: =W36+X35 -> 314988 | AA36: Salsa Lv2
A37: Tortilla de Cangrejo .3 | B37: 6076 | C37: Dusthole Crab | D37: 1 | E37: Bundle of corn | F37: 6 | G37: Firetouched mullein | H37: 6 | I37: Raw pork | J37: 6 | M37: Salsa Lv3 | N37: 27 | O37: 1 | Q37: 750 | R37: Tortillas | S37: 116 | T37: 56 | V37: 36 | W37: 17208 | X37: =W37+X36 -> 332196 | AA37: Salsa Lv3
A38: Cerdo Asado | B38: 5280 | C38: Bundle of corn | D38: 36 | E38: Raw pork | F38: 72 | G38: Cow's milk | H38: 36 | N38: 90 | O38: 10 | P38: 4320 | Q38: 576 | R38: Asados | S38: 116 | T38: 56 | V38: 37 | W38: 17844 | X38: =W38+X37 -> 350040 | AA38: Energia Ava.
A39: Cerdo Asado .1 | B39: 7280 | C39: Bundle of corn | D39: 36 | E39: Raw pork | F39: 72 | G39: Cow's milk | H39: 36 | M39: Salsa Lv1 | N39: 90 | O39: 10 | P39: 4320 | Q39: 576 | R39: Asados | S39: 132 | T39: 64 | V39: 38 | W39: 18500 | X39: =W39+X38 -> 368540 | AA39: Tortilla de Pollo
A40: Cerdo Asado .2 | B40: 11280 | C40: Bundle of corn | D40: 36 | E40: Raw pork | F40: 72 | G40: Cow's milk | H40: 36 | M40: Salsa Lv2 | N40: 90 | O40: 10 | P40: 4320 | Q40: 576 | R40: Asados | S40: 396 | T40: 192 | V40: 39 | W40: 19176 | X40: =W40+X39 -> 387716 | AA40: Tortilla de Ganso
...

Sheet Cocina
E2: COCINA BÁSICA 1.3 | N2: Dave Okey
H4: Instrucciones | N4: Dave Okey
C6: Niveles / Specs | N6: Albion En Español
C8: Cocinero | E8: 100 | F8: Tortillas | H8: 100
C9: Carniceria | E9: 100 | F9: Ensaladas | H9: 100
C10: Ingredientes | E10: 51 | F10: Pasteles | H10: 77 | M10: CONFIGURACIÓN
C11: Bocadillos | E11: 100 | F11: Asados | H11: 100
C12: Guisos | E12: 100 | F12: Sopas | H12: 100 | M12: Premium | N12: TRUE | O12: Coste de Estacion | P12: 590
M13: Foco | N13: TRUE | O13: R. de Recursos | P13: =Calculos!G5 -> 0.43502825
M14: Bono de Ciudad | N14: FALSE | O14: Impuestos | P14: =IF(N12,0.065,0.105) -> 0.065
C15: Platillo
C16: Guiso de Ternera
M17: Costo de Fabrica | N17: Precio Venta | O17: Ganancias | P17: Foco | Q17: Plata/Foco
C19: Lista de Compras | L19: =IFERROR(VLOOKUP($C$16,Recetas!AA39:AB110,2,0), "") | M19: =IF(L19 = "", "", Calculos!D21) -> 3935.5403 | O19: =IF($L19 = "", "",Calculos!G21 ) -> 0 | P19: =IF($L19 = "", "",Calculos!I21 ) -> 0 | Q19: =IF($L19 = "", "",Calculos!H21 ) -> -14.554247
C20: # | D20: Item | F20: Cantidad | G20: Precio | H20: Total
C21: =IF(E21 <> "", VLOOKUP(E21,Calculos!$D$2:$F$9,3,0),"") -> 1 | D21: =IFERROR(VLOOKUP(E21,Recetas!$AA$1:$AB$38,2,0), "") | E21: =Calculos!D2 -> Raw beef | F21: =Calculos!K28*(1-P13) -> 2806.7797 | G21: 409 | H21: =IF(G21 = "", "", F21*G21) -> 1147972.9
C22: =IF(E22 <> "", VLOOKUP(E22,Calculos!$D$2:$F$9,3,0),"") -> 2 | D22: =IFERROR(VLOOKUP(E22,Recetas!$AA$1:$AB$38,2,0), "") | E22: =Calculos!D3 -> Pumpkin | F22: =Calculos!M28*(1-P13) -> 1403.3898 | G22: 495 | H22: =IF(G22 = "", "", F22*G22) -> 694677.97 | L22: =IFERROR(VLOOKUP($C$16 & " .1",Recetas!AA39:AB113,2,0), "") | M22: =IF(L22 = "", "", Calculos!D23) -> 23003.337 | O22: =IF(L22 = "", "",Calculos!G23 ) -> 1760207.9 | P22: =IF($L22 = "", "",Calculos!I23 ) -> 8685.3607 | Q22: =IF($L22 = "", "",Calculos!H23 ) -> 202.66376
C23: =IF(E23 <> "", VLOOKUP(E23,Calculos!$D$2:$F$9,3,0),"") -> 3 | D23: =IFERROR(VLOOKUP(E23,Recetas!$AA$1:$AB$38,2,0), "") | E23: =Calculos!D4 -> Bread | F23: =Calculos!O28*(1-P13) -> 1403.3898 | G23: 434 | H23: =IF(G23 = "", "", F23*G23) -> 609071.19 | K23: 45
C24: =IF(E24 <> "", VLOOKUP(E24,Calculos!$D$2:$F$9,3,0),"") | D24: =IFERROR(VLOOKUP(E24,Recetas!$AA$1:$AB$38,2,0), "") | E24: =Calculos!D5 | F24: =Calculos!Q28*(1-P13) -> 0 | G24: 245 | H24: =IF(G24 = "", "", F24*G24) -> 0
C25: =IF(E25 <> "", VLOOKUP(E25,Calculos!$D$2:$F$9,3,0),"") -> 4 | D25: =IFERROR(VLOOKUP(E25,Recetas!$AA$1:$AB$38,2,0), "") | E25: =Calculos!D6 -> Salsa Lv1 | F25: =Calculos!S28*(1-$P$13) -> 2288.1356 | G25: 3750 | H25: =IF(G25 = "", "", F25*G25) -> 8580508.5 | L25: =IFERROR(VLOOKUP($C$16 & " .2",Recetas!AA39:AB116,2,0), "") | M25: =IF(L25 = "", "", Calculos!D25) -> 62410.117 | O25: =IF(L25 = "", "",Calculos!G25 ) -> 2524772 | P25: =IF($L25 = "", "",Calculos!I25 ) -> 7096.1245 | Q25: =IF($L25 = "", "",Calculos!H25 ) -> 355.7959
C26: =IF(E26 <> "", VLOOKUP(E26,Calculos!$D$2:$F$9,3,0),"") -> 5 | D26: =IFERROR(VLOOKUP(E26,Recetas!$AA$1:$AB$38,2,0), "") | E26: =Calculos!D7 -> Salsa Lv2 | F26: =Calculos!S29*(1-$P$13) -> 1220.339 | G26: 11500 | H26: =IF(G26 = "", "", F26*G26) -> 14033898 | K26: 24
C27: =IF(E27 <> "", VLOOKUP(E27,Calculos!$D$2:$F$9,3,0),"") -> 6 | D27: =IFERROR(VLOOKUP(E27,Recetas!$AA$1:$AB$38,2,0), "") | E27: =Calculos!D8 -> Salsa Lv3 | F27: =Calculos!S30*(1-$P$13) -> 0 | G27: 33502 | H27: =IF(G27 = "", "", F27*G27) -> 0
C28: =IF(E28 <> "", VLOOKUP(E28,Calculos!$D$2:$F$9,3,0),"") -> 7 | D28: =IFERROR(VLOOKUP(E28,Recetas!$AA$1:$AB$38,2,0), "") | E28: =Calculos!D9 -> Energia Ava. | F28: =Calculos!U28 -> 0 | G28: =IF(E28 <> "",VLOOKUP(E28,'Lista de Precios'!B5:D59,3,0),"") -> 3612 | H28: =IF(G28 = "", "", F28*G28) -> 0 | L28: =IFERROR(VLOOKUP($C$16 & " .3",Recetas!AA39:AB119,2,0), "") | M28: =IF(L28 = "", "", Calculos!D27) -> 174284.69 | O28: =IF(L28 = "", "",Calculos!G27 ) -> 0 | P28: =IF($L28 = "", "",Calculos!I27 ) -> 0 | Q28: =IF($L28 = "", "",Calculos!H27 ) -> 179.58184
C29: =IF(E29 <> "", VLOOKUP(E29,Calculos!$D$2:$F$9,3,0),"") | G29: Total: | H29: =SUM(H21:H28) -> 25066129
C30: Inversion total (Comision + Material): | H30: =H29+Calculos!AA28 -> 25329930
L31: 2 | N31: TOTAL | O31: =SUM(O19:O30) -> 4284979.9 | P31: =SUM(P19:P30) -> 15781.485 | Q31: =(SUM(Q19:Q30)/(4-COUNTBLANK(Q19,Q22,Q25,Q28))) -> 180.87182
C34: Llena los precios AQUÍ

Sheet Power Level  Study
S1: 0 | T1: 0 | U1: 0
H2: Receta | I2: Precio | J2: Costo de Estudio | K2: Plata/Fama | L2: Restantes | M2: Costo Total | S2: 1 | T2: 3564 | U2: =T2 -> 3564
B3: POWER-LEVEL DE COCINA | G3: =VLOOKUP(H3,Recetas!AA1:AB110,2,0) | H3: Sopa de Zanahorias | I3: 200 | J3: =ROUNDDOWN((0.1125*Recetas!T34*($C$5/10))/10,0) -> 24 | K3: =(I3+J3)/Recetas!S34 -> 1.6969697 | L3: =($F$11/Recetas!S34) -> 25656.333 | M3: =(I3+J3)*L3 -> 5747018.7 | S3: 2 | T3: 3784 | U3: =T3+U2 -> 7348
G4: =VLOOKUP(H4,Recetas!AA2:AB111,2,0) | H4: Ensalada de Frijoles | I4: 426 | J4: =ROUNDDOWN((0.1125*Recetas!T35*($C$5/10))/10,0) -> 24 | K4: =(I4+J4)/Recetas!S35 -> 3.4090909 | L4: =($F$12/Recetas!S35) -> 25656.333 | M4: =(I4+J4)*L4 -> 11545350 | S4: 3 | T4: 4008 | U4: =T4+U3 -> 11356
B5: Estacion | C5: 335 | G5: =VLOOKUP(H5,Recetas!AA3:AB112,2,0) | H5: Sopa de Trigo | I5: 1085 | J5: =ROUNDDOWN((0.1125*Recetas!T36*($C$5/10))/10,0) -> 72 | K5: =(I5+J5)/Recetas!S36 -> 2.9217172 | L5: =($F$11/Recetas!S36) -> 8552.1111 | M5: =(I5+J5)*L5 -> 9894792.6 | S5: 4 | T5: 4240 | U5: =T5+U4 -> 15596
G6: =VLOOKUP(H6,Recetas!AA4:AB113,2,0) | H6: Pastel de Pollo | I6: 402 | J6: =ROUNDDOWN((0.1125*Recetas!T37*($C$5/10))/10,0) -> 21 | K6: =(I6+J6)/Recetas!S37 -> 3.6465517 | L6: =($F$14/Recetas!S37) -> 25944.517 | M6: =(I6+J6)*L6 -> 10974531 | S6: 5 | T6: 4480 | U6: =T6+U5 -> 20076
B7: Masteries | C7: Nivel Actual | D7: Fama actual | E7: Nivel Meta | F7: Fama Requerida | G7: =VLOOKUP(H7,Recetas!AA5:AB114,2,0) | H7: Tortilla de Pollo | I7: 308 | J7: =ROUNDDOWN((0.1125*Recetas!T38*($C$5/10))/10,0) -> 21 | K7: =(I7+J7)/Recetas!S38 -> 2.8362069 | L7: =($F$15/Recetas!S38) -> 0 | M7: =(I7+J7)*L7 -> 0 | S7: 6 | T7: 4728 | U7: =T7+U6 -> 24804
B8: Ingrediente | C8: 51 | D8: 0 | E8: 100 | F8: =IFERROR(IF(INDEX($U$2:$U$101,E8,1)-INDEX($U$2:$U$101,C8,1)-D8 < 0, 0, INDEX($U$2:$U$101,E8,1)-INDEX($U$2:$U$101,C8,1)-D8), 0) -> 3357664 | G8: =VLOOKUP(H8,Recetas!AA6:AB115,2,0) | H8: Pollo Asado | I8: 273 | J8: =ROUNDDOWN((0.1125*Recetas!T39*($C$5/10))/10,0) -> 24 | K8: =(I8+J8)/Recetas!S39 -> 2.25 | L8: =($F$9/Recetas!S39) -> 24224.394 | M8: =(I8+J8)*L8 -> 7194645 | S8: 7 | T8: 4988 | U8: =T8+U7 -> 29792
B9: Asados | C9: 56 | D9: 0 | E9: 100 | F9: =IFERROR(IF(INDEX($U$2:$U$101,E9,1)-INDEX($U$2:$U$101,C9,1)-D9 < 0, 0, INDEX($U$2:$U$101,E9,1)-INDEX($U$2:$U$101,C9,1)-D9), 0) -> 3197620 | G9: =VLOOKUP(H9,Recetas!AA7:AB116,2,0) | H9: Ensalada de Rábanos | I9: 1681 | J9: =ROUNDDOWN((0.1125*Recetas!T40*($C$5/10))/10,0) -> 72 | K9: =(I9+J9)/Recetas!S40 -> 4.4267677 | L9: =($F$12/Recetas!S40) -> 8552.1111 | M9: =(I9+J9)*L9 -> 14991851 | S9: 8 | T9: 5252 | U9: =T9+U8 -> 35044
B10: Guisos | C10: 100 | D10: 0 | E10: 100 | F10: =IFERROR(IF(INDEX($U$2:$U$101,E10,1)-INDEX($U$2:$U$101,C10,1)-D10 < 0, 0, INDEX($U$2:$U$101,E10,1)-INDEX($U$2:$U$101,C10,1)-D10), 0) -> 0 | G10: =VLOOKUP(H10,Recetas!AA8:AB117,2,0) | H10: Guiso de Cabra | I10: 349 | J10: =ROUNDDOWN((0.1125*Recetas!T41*($C$5/10))/10,0) -> 24 | K10: =(I10+J10)/Recetas!S41 -> 2.8257576 | L10: =($F$10/Recetas!S41) -> 0 | M10: =(I10+J10)*L10 -> 0 | S10: 9 | T10: 5524 | U10: =T10+U9 -> 40568
B11: Sopas | C11: 50 | D11: 0 | E11: 100 | F11: =IFERROR(IF(INDEX($U$2:$U$101,E11,1)-INDEX($U$2:$U$101,C11,1)-D11 < 0, 0, INDEX($U$2:$U$101,E11,1)-INDEX($U$2:$U$101,C11,1)-D11), 0) -> 3386636 | G11: =VLOOKUP(H11,Recetas!AA9:AB118,2,0) | H11: Bocadillo de Cabra | I11: 197 | J11: =ROUNDDOWN((0.1125*Recetas!T43*($C$5/10))/10,0) -> 21 | K11: =(I11+J11)/Recetas!S43 -> 1.8793103 | L11: =($F$13/Recetas!S43) -> 31928.345 | M11: =(I11+J11)*L11 -> 6960379.2 | S11: 10 | T11: 5808 | U11: =T11+U10 -> 46376
B12: Ensaladas | C12: 50 | D12: 0 | E12: 100 | F12: =IFERROR(IF(INDEX($U$2:$U$101,E12,1)-INDEX($U$2:$U$101,C12,1)-D12 < 0, 0, INDEX($U$2:$U$101,E12,1)-INDEX($U$2:$U$101,C12,1)-D12), 0) -> 3386636 | G12: =VLOOKUP(H12,Recetas!AA10:AB119,2,0) | H12: Sopa de Col | I12: 3174 | J12: =ROUNDDOWN((0.1125*Recetas!T44*($C$5/10))/10,0) -> 217 | K12: =(I12+J12)/Recetas!S44 -> 2.8543771 | L12: =($F$11/Recetas!S44) -> 2850.7037 | M12: =(I12+J12)*L12 -> 9666736.3 | S12: 11 | T12: 6100 | U12: =T12+U11 -> 52476
B13: Bocadilo | C13: 36 | D13: 0 | E13: 100 | F13: =IFERROR(IF(INDEX($U$2:$U$101,E13,1)-INDEX($U$2:$U$101,C13,1)-D13 < 0, 0, INDEX($U$2:$U$101,E13,1)-INDEX($U$2:$U$101,C13,1)-D13), 0) -> 3703688 | G13: =VLOOKUP(H13,Recetas!AA11:AB120,2,0) | H13: Pastel de Ganso | I13: 1396 | J13: =ROUNDDOWN((0.1125*Recetas!T45*($C$5/10))/10,0) -> 72 | K13: =(I13+J13)/Recetas!S45 -> 3.7070707 | L13: =($F$14/Recetas!S45) -> 7599.9091 | M13: =(I13+J13)*L13 -> 11156667 | S13: 12 | T13: 6400 | U13: =T13+U12 -> 58876
B14: Pastel | C14: 61 | D14: 0 | E14: 100 | F14: =IFERROR(IF(INDEX($U$2:$U$101,E14,1)-INDEX($U$2:$U$101,C14,1)-D14 < 0, 0, INDEX($U$2:$U$101,E14,1)-INDEX($U$2:$U$101,C14,1)-D14), 0) -> 3009564 | G14: =VLOOKUP(H14,Recetas!AA12:AB121,2,0) | H14: Tortilla de Ganso | I14: 890 | J14: =ROUNDDOWN((0.1125*Recetas!T46*($C$5/10))/10,0) -> 63 | K14: =(I14+J14)/Recetas!S46 -> 2.7543353 | L14: =($F$15/Recetas!S46) -> 0 | M14: =(I14+J14)*L14 -> 0 | S14: 13 | T14: 6712 | U14: =T14+U13 -> 65588
B15: Tortillas | C15: 100 | D15: 0 | E15: 100 | F15: =IFERROR(IF(INDEX($U$2:$U$101,E15,1)-INDEX($U$2:$U$101,C15,1)-D15 < 0, 0, INDEX($U$2:$U$101,E15,1)-INDEX($U$2:$U$101,C15,1)-D15), 0) -> 0 | G15: =VLOOKUP(H15,Recetas!AA13:AB122,2,0) | H15: Ganso Asado | I15: 945 | J15: =ROUNDDOWN((0.1125*Recetas!T47*($C$5/10))/10,0) -> 72 | K15: =(I15+J15)/Recetas!S47 -> 2.5681818 | L15: =($F$9/Recetas!S47) -> 8074.798 | M15: =(I15+J15)*L15 -> 8212069.5 | S15: 14 | T15: 7032 | U15: =T15+U14 -> 72620
G16: =VLOOKUP(H16,Recetas!AA14:AB123,2,0) | H16: Ensalada de Patatas | I16: 3545 | J16: =ROUNDDOWN((0.1125*Recetas!T49*($C$5/10))/10,0) -> 217 | K16: =(I16+J16)/Recetas!S49 -> 3.1666667 | L16: =($F$12/Recetas!S49) -> 2850.7037 | M16: =(I16+J16)*L16 -> 10724347 | S16: 15 | T16: 7364 | U16: =T16+U15 -> 79984
G17: =VLOOKUP(H17,Recetas!AA15:AB124,2,0) | H17: Ensalada de Kraken | I17: 19997 | J17: =ROUNDDOWN((0.1125*Recetas!T50*($C$5/10))/10,0) -> 282 | K17: =(I17+J17)/Recetas!S50 -> 13.655892 | L17: =($F$12/Recetas!S50) -> 2280.563 | M17: =(I17+J17)*L17 -> 46247536 | S17: 16 | T17: 7704 | U17: =T17+U16 -> 87688
C18: Dave Okey | G18: =VLOOKUP(H18,Recetas!AA16:AB125,2,0) | H18: Guiso de Carnero | I18: 1480 | J18: =ROUNDDOWN((0.1125*Recetas!T51*($C$5/10))/10,0) -> 72 | K18: =(I18+J18)/Recetas!S51 -> 3.9191919 | L18: =($F$10/Recetas!S51) -> 0 | M18: =(I18+J18)*L18 -> 0 | S18: 17 | T18: 8056 | U18: =T18+U17 -> 95744
G19: =VLOOKUP(H19,Recetas!AA17:AB126,2,0) | H19: Bocadillo de Carnero | I19: 1494 | J19: =ROUNDDOWN((0.1125*Recetas!T53*($C$5/10))/10,0) -> 63 | K19: =(I19+J19)/Recetas!S53 -> 4.5 | L19: =($F$13/Recetas!S53) -> 10704.301 | M19: =(I19+J19)*L19 -> 16666596 | S19: 18 | T19: 8420 | U19: =T19+U18 -> 104164
C20: Dave Okey | G20: =VLOOKUP(H20,Recetas!AA18:AB127,2,0) | H20: Pastel de Cerdo | I20: 3191 | J20: =ROUNDDOWN((0.1125*Recetas!T55*($C$5/10))/10,0) -> 217 | K20: =(I20+J20)/Recetas!S55 -> 2.8686869 | L20: =($F$14/Recetas!S55) -> 2533.303 | M20: =(I20+J20)*L20 -> 8633496.7 | S20: 19 | T20: 8792 | U20: =T20+U19 -> 112956
G21: =VLOOKUP(H21,Recetas!AA19:AB128,2,0) | H21: Tortilla de Cerdo | I21: 3145 | J21: =ROUNDDOWN((0.1125*Recetas!T57*($C$5/10))/10,0) -> 189 | K21: =(I21+J21)/Recetas!S57 -> 3.2088547 | L21: =($F$15/Recetas!S57) -> 0 | M21: =(I21+J21)*L21 -> 0 | S21: 20 | T21: 9176 | U21: =T21+U20 -> 122132
C22: Albion En Español | G22: =VLOOKUP(H22,Recetas!AA20:AB129,2,0) | H22: Cerdo Asado | I22: 3074 | J22: =ROUNDDOWN((0.1125*Recetas!T59*($C$5/10))/10,0) -> 217 | K22: =(I22+J22)/Recetas!S59 -> 2.770202 | L22: =($F$9/Recetas!S59) -> 2691.5993 | M22: =(I22+J22)*L22 -> 8858053.4 | S22: 21 | T22: 9576 | U22: =T22+U21 -> 131708
G23: =VLOOKUP(H23,Recetas!AA21:AB130,2,0) | H23: Guiso de Ternera | I23: 3481 | J23: =ROUNDDOWN((0.1125*Recetas!T60*($C$5/10))/10,0) -> 217 | K23: =(I23+J23)/Recetas!S60 -> 3.1127946 | L23: =($F$10/Recetas!S60) -> 0 | M23: =(I23+J23)*L23 -> 0 | S23: 22 | T23: 9984 | U23: =T23+U22 -> 141692
H24: Guiso de Anguila | I24: 64992 | J24: =ROUNDDOWN((0.1125*Recetas!T61*($C$5/10))/10,0) -> 282 | K24: =(I24+J24)/Recetas!S61 -> 43.955556 | L24: =($F$10/Recetas!S61) -> 0 | M24: =(I24+J24)*L24 -> 0 | S24: 23 | T24: 10408 | U24: =T24+U23 -> 152100
G25: =VLOOKUP(H25,Recetas!AA23:AB132,2,0) | H25: Bocadillo de Ternera | I25: 2979 | J25: =ROUNDDOWN((0.1125*Recetas!T62*($C$5/10))/10,0) -> 189 | K25: =(I25+J25)/Recetas!S62 -> 3.0490857 | L25: =($F$13/Recetas!S62) -> 3564.666 | M25: =(I25+J25)*L25 -> 11292862 | S25: 24 | T25: 10844 | U25: =T25+U24 -> 162944
G26: =VLOOKUP(H26,Recetas!AA24:AB133,2,0) | H26: Bocadillo de Locha | I26: 22463 | J26: =ROUNDDOWN((0.1125*Recetas!T63*($C$5/10))/10,0) -> 282 | K26: =(I26+J26)/Recetas!S63 -> 15.316498 | L26: =($F$13/Recetas!S63) -> 2494.066 | M26: =(I26+J26)*L26 -> 56727531 | S26: 25 | T26: 11292 | U26: =T26+U25 -> 174236
H27: Pan | I27: 277 | J27: =ROUNDDOWN((0.1125*Recetas!T64*($C$5/10))/10,0) -> 15 | K27: =(I27+J27)/Recetas!S64 -> 2.6306306 | L27: =($F$8/Recetas!S64) -> 30249.225 | M27: =(I27+J27)*L27 -> 8832773.8 | S27: 26 | T27: 11752 | U27: =T27+U26 -> 185988
S28: 27 | T28: 12228 | U28: =T28+U27 -> 198216
S29: 28 | T29: 12720 | U29: =T29+U28 -> 210936
S30: 29 | T30: 13224 | U30: =T30+U29 -> 224160
S31: 30 | T31: 13744 | U31: =T31+U30 -> 237904
S32: 31 | T32: 14280 | U32: =T32+U31 -> 252184
S33: 32 | T33: 14832 | U33: =T33+U32 -> 267016
S34: 33 | T34: 15400 | U34: =T34+U33 -> 282416
S35: 34 | T35: 15984 | U35: =T35+U34 -> 298400
S36: 35 | T36: 16588 | U36: =T36+U35 -> 314988
S37: 36 | T37: 17208 | U37: =T37+U36 -> 332196
S38: 37 | T38: 17844 | U38: =T38+U37 -> 350040
S39: 38 | T39: 18500 | U39: =T39+U38 -> 368540
... S101: 100 | T101: 126568 | U101: =T101+U100 -> 4035884

Sheet Lista de Precios
B4: VEGGIES | C4: Icono | D4: Precio | F4: Plato | G4: Plato | H4: Precio
B5: Carrot | F5: Tortilla de Pollo
B6: Bean | F6: Tortilla de Ganso
B7: Wheat | D7: 427 | F7: Tortilla de Cerdo | H7: 3875
B8: Turnip | D8: 455 | F8: Tortilla de Cerdo .1 | H8: 32783
B9: Cabbage | D9: 472 | F9: Tortilla de Cerdo .2 | H9: 85999
B10: Potatoes | D10: 400 | F10: Tortilla de Cerdo .3 | H10: 230979
B11: Bundle of corn | D11: 415 | F11: Tortilla de Cangrejo
B12: Pumpkin | D12: 428 | F12: Tortilla de Cangrejo .1
F13: Tortilla de Cangrejo .2
B14: HERBS | C14: Icono | D14: Precio | F14: Tortilla de Cangrejo .3
B15: Dragon teasel
B16: Elusive Foxglove | F16: Plato | G16: Plato | H16: Precio
B17: Firetouched mullein | F17: Pastel de Pollo
B18: Ghoul Yarrow | F18: Pastel de Ganso
F19: Pastel de Cerdo | H19: 4282
B20: CARNES | C20: Icono | D20: Precio | F20: Pastel de Cerdo .1 | H20: 30768
B21: Raw chicken | F21: Pastel de Cerdo .2 | H21: 78897
B22: Raw goat | F22: Pastel de Cerdo .3 | H22: 209161
B23: Raw Goose | F23: Pastel de Ojo Muerto
B24: Raw mutton | F24: Pastel de Ojo Muerto .1
B25: Raw pork | D25: 409 | F25: Pastel de Ojo Muerto .2
B26: Raw beef | D26: 320 | F26: Pastel de Ojo Muerto .3
B28: PRODUCTOS | C28: Icono | D28: Precio | F28: Plato | G28: Plato | H28: Precio
B29: Hen eggs | F29: Guiso de Cabra
B30: Flour | F30: Guiso de Carnero
B31: Bread | D31: 328 | F31: Guiso de Ternera | H31: 3989
B32: Goat's butter | F32: Guiso de Ternera .1 | H32: 28786
B33: Goat's milk | F33: Guiso de Ternera .2 | H33: 78000
B34: Goose eggs | D34: 290 | F34: Guiso de Ternera .3 | H34: 198000
B35: sheep's butter | F35: Guiso de Anguila Agua Podrida | H35: 63281
B36: Sheep's milk | D36: 315 | F36: Guiso de Anguila Agua Podrida .1 | H36: 150017
B37: Cow's milk | D37: 240 | F37: Guiso de Anguila Agua Podrida .2 | H37: 302999
B38: Cow's butter | F38: Guiso de Anguila Agua Podrida .3 | H38: 584998
B40: PECES | C40: Icono | D40: Precio | F40: Plato | G40: Plato | H40: Precio
B41: Deepwater Kraken | D41: 22499 | F41: Pollo Asado
B42: Frostpeak Deadeye | F42: Ganso Asado
B43: Dusthole Crab | F43: Cerdo Asado
B44: Deadwater Eel | D44: 83994 | F44: Cerdo Asado .1
B45: Puremist Snapper | F45: Cerdo Asado .2
...
